Workbook
Name Sites: OFFSET(Lists!$C$2,0,0,SUMPRODUCT(--(Table3[CompanyList]<>"")),1)

Sheet Welcome
B1: DO NOT REMOVE OR EDIT INFORMATION IN THIS SECTION FOR INTERNAL USE ONLY
A2: Template Name | B2: 60.5422a Semiannual Report (Spreadsheet Template)
A3: CitationID | B3: 60.5422a
A4: Template Version | B4: v2.01
A5: Last Updated Date | B5: 45475
B6: OMB Control Number: 2060-0721 Form 5900-649 For further Paperwork Reduction Act information see: https://www.epa.gov/electronic-reporting-air-emissions/paperwork-reduction-act-pra-cedri-and-ert
B7: For further Paperwork Reduction Act information see: https://www.epa.gov/electronic-reporting-air-emissions/paperwork-reduction-act-pra-cedri-and-ert
B8: 40 CFR Part 60, Subpart OOOOa Standards of Performance for Crude Oil and Natural Gas Facilities for which Construction, Modification or Reconstruction Commenced After September 18, 2015, and on or before December 6, 2022 - §60.5422a(a) and (b) Semiannual Report Spreadsheet Template
B9: Instructions for Spreadsheet Template
B10: Purpose: This spreadsheet template was designed by the U.S. EPA to facilitate semiannual reporting for process unit equipment affected facilities subject under 40 CFR part 60, subpart OOOOa New Source Performance Standard for Crude Oil and Natural Gas Facilities Constructed, Modified, or Reconstructed after September 18, 2015, and on or before December 6, 2022.
B11: Electronic reporting: Electronic submission of semiannual reports through the EPA's Compliance and Emissions Data Reporting (CEDRI) is required under §60.5422b and §60.5422c. CEDRI is accessed through the EPA's Central Data Exchange (https://cdx.epa.gov).
B12: Confidential Business Information:
B13: Do not submit confidential business information (CBI) to EPA via CEDRI. EPA will make all the information submitted through this form via CEDRI available to the public without further notice to you. All CBI claims must be asserted at the time of submission. Anything submitted using CEDRI cannot later be claimed to be CBI. Furthermore, under CAA section 114(c) emissions data is not entitled to confidential treatment, and EPA is required to make emissions data available to the public. Thus, emissions data will not be protected as CBI and will be made publicly available.
B14: Although we do not expect persons to assert a claim of CBI, if persons wish to assert a CBI claim for some of the information in this report, you must submit a version of the report with the CBI omitted via CEDRI and submit a complete report, including any information claimed to be CBI, to EPA. The preferred method to receive CBI is for it to be transmitted electronically using email attachments, File Transfer Protocol, or other online file sharing services. Electronic submissions must be transmitted directly to the OAQPS CBI Office at the email address oaqpscbi@epa.gov to the attention of the Oil and Gas Sector Lead. If assistance is needed with submitting large electronic files that exceed the file size limit for email attachments, and if you do not have your own file sharing service, please email oaqpscbi@epa.gov to request a file transfer link. If you cannot transmit the file electronically, you may send CBI information through the postal service to the following address:
B15: OAQPS Document Control Officer (C404-02) OAQPS, U.S. Environmental Protection Agency Attn: Oil and Gas Sector Lead 109 T.W. Alexander Drive P.O. Box 12055 Research Triangle Park, North Carolina 27711
B16: The mailed CBI material should be double wrapped and clearly marked. Any CBI markings should not show through the outer envelope. Clearly mark the part or all of the information that you claim to be CBI. Information not marked as CBI may be authorized for public release without prior notice. Information marked as CBI will not be disclosed except in accordance with procedures set forth in 40 CFR part 2.
B17: Using this Template:
... B24: Within each worksheet, example rows are colored light orange (rows 14 through 23), and the XML tag row (row 13) is colored green. These rows are locked; no data entry is made in these rows.

Sheet Site_Information
B1: =Welcome!A1 -> 0
B2: =Welcome!A2 -> Template Name | C2: =Welcome!B2 -> 60.5422a Semiannual Report (Spreadsheet Template)
B3: =Welcome!A3 -> CitationID | C3: =Welcome!B3 -> 60.5422a
B4: =Welcome!A4 -> Template Version | C4: =Welcome!B4 -> v2.01
B5: =Welcome!A5 -> Last Updated Date | C5: =Welcome!B5 -> 45475
B7: 40 CFR Part 60 - Standards of Performance for Crude Oil and Natural Gas Facilities for which Construction, Modification or Reconstruction Commenced After September 18, 2015, and on or before December 6, 2022 - 60.5422a Semiannual Report
B9: Use this tab to provide information on the sites for which you are reporting.
B10: Note: The Site Record No. will automatically generate if you do not enter one.
B11: FACILITY INFORMATION | K11: REPORTING PERIOD | M11: ADDITIONAL INFORMATION
B12: Site Record No. (Field value will automatically generate if a value is not entered) | C12: Site Name | D12: Address of Processing Plant | E12: Address 2 | F12: City | G12: County | H12: State Abbreviation | I12: Zip Code | J12: Responsible Agency Facility ID (State Facility Identifier) | K12: Beginning Date of Reporting Period | L12: Ending Date of Reporting Period | M12: Please enter any additional information | N12: Enter associated file name reference.
B13: RecordId | C13: FacilityName | D13: AddressLine1 | E13: AddressLine2 | F13: CityName | G13: CountyName | H13: StateName | I13: ZIPCode | J13: StateFacID | K13: PeriodStartDate | L13: PeriodEndDate | M13: AddInfo | N13: AddFile
B14: e.g.: 1 | C14: e.g.: ABC Company | D14: e.g.: 123 Main Street | E14: e.g.: Suite 100 | F14: e.g.: Brooklyn | G14: e.g.: Kings County | H14: e.g.: NY | I14: e.g.: 11221 | J14: e.g.: | K14: e.g.: 01/01/2016 | L14: e.g.: 06/30/2016 | N14: e.g.: filename.pdf
B15: e.g.: | C15: e.g.: | D15: e.g.: | E15: e.g.: | F15: e.g.: | G15: e.g.: | H15: e.g.: | I15: e.g.: | J15: e.g.: | K15: e.g.: | L15: e.g.: | M15: e.g.: | N15: e.g.:
B16: e.g.: | C16: e.g.: | D16: e.g.: | E16: e.g.: | F16: e.g.: | G16: e.g.: | H16: e.g.: | I16: e.g.: | J16: e.g.: | K16: e.g.: | L16: e.g.: | M16: e.g.: | N16: e.g.:
B17: e.g.: | C17: e.g.: | D17: e.g.: | E17: e.g.: | F17: e.g.: | G17: e.g.: | H17: e.g.: | I17: e.g.: | J17: e.g.: | K17: e.g.: | L17: e.g.: | M17: e.g.: | N17: e.g.:
B18: e.g.: | C18: e.g.: | D18: e.g.: | E18: e.g.: | F18: e.g.: | G18: e.g.: | H18: e.g.: | I18: e.g.: | J18: e.g.: | K18: e.g.: | L18: e.g.: | M18: e.g.: | N18: e.g.:
B19: e.g.: | C19: e.g.: | D19: e.g.: | E19: e.g.: | F19: e.g.: | G19: e.g.: | H19: e.g.: | I19: e.g.: | J19: e.g.: | K19: e.g.: | L19: e.g.: | M19: e.g.: | N19: e.g.:
B20: e.g.: | C20: e.g.: | D20: e.g.: | E20: e.g.: | F20: e.g.: | G20: e.g.: | H20: e.g.: | I20: e.g.: | J20: e.g.: | K20: e.g.: | L20: e.g.: | M20: e.g.: | N20: e.g.:
B21: e.g.: | C21: e.g.: | D21: e.g.: | E21: e.g.: | F21: e.g.: | G21: e.g.: | H21: e.g.: | I21: e.g.: | J21: e.g.: | K21: e.g.: | L21: e.g.: | M21: e.g.: | N21: e.g.:
B22: e.g.: | C22: e.g.: | D22: e.g.: | E22: e.g.: | F22: e.g.: | G22: e.g.: | H22: e.g.: | I22: e.g.: | J22: e.g.: | K22: e.g.: | L22: e.g.: | M22: e.g.: | N22: e.g.:
B23: e.g.: | C23: e.g.: | D23: e.g.: | E23: e.g.: | F23: e.g.: | G23: e.g.: | H23: e.g.: | I23: e.g.: | J23: e.g.: | K23: e.g.: | L23: e.g.: | M23: e.g.: | N23: e.g.:
B24: DC2 | C24: ONEOK Hydrocarbon, L.P. - Hutchinson Fractionation Facility; Process Unit: DC2 | D24: 1910 South Broadacres Road | F24: Hutchinson | G24: Reno County | H24: KS | I24: 67501 | J24: 1550011 | K24: 45627 | L24: 45808 | M24: During the report period, one valve was signed off on the LDAR DOR (ID#42556 signed off on 3/18/2025). Prior to report period, there were two valves on the LDAR DOR (ID# 40266 signed off as LDAR DOR on 11/20/2024 and ID# 118977 signed off as LDAR DOR on 11/21/2024). The DC2 process unit had one shutdown during the reporting period; 3/26/2025 to 5/1/2025. All three DOR valves were determined to be below leak defintion during early May 2025.
B25: =IF(C25="","",ROW(B25)-23)
B26: =IF(C26="","",ROW(B26)-23)
B27: =IF(C27="","",ROW(B27)-23)
B28: =IF(C28="","",ROW(B28)-23)
B29: =IF(C29="","",ROW(B29)-23)
B30: =IF(C30="","",ROW(B30)-23)
B31: =IF(C31="","",ROW(B31)-23)
B32: =IF(C32="","",ROW(B32)-23)
B33: =IF(C33="","",ROW(B33)-23)
B34: =IF(C34="","",ROW(B34)-23)
B35: =IF(C35="","",ROW(B35)-23)
B36: =IF(C36="","",ROW(B36)-23)
... B223: =IF(C223="","",ROW(B223)-23)
B224: =IF(C224="","",ROW(B224)-6)
B225: =IF(C225="","",ROW(B225)-6)
B226: =IF(C226="","",ROW(B226)-6)
B227: =IF(C227="","",ROW(B227)-6)
B228: =IF(C228="","",ROW(B228)-6)
...

Sheet Initial_Report
B1: =Welcome!A1 -> 0
B2: =Welcome!A2 -> Template Name | C2: =Welcome!B2 -> 60.5422a Semiannual Report (Spreadsheet Template)
B3: =Welcome!A3 -> CitationID | C3: =Welcome!B3 -> 60.5422a
B4: =Welcome!A4 -> Template Version | C4: =Welcome!B4 -> v2.01
B5: =Welcome!A5 -> Last Updated Date | C5: =Welcome!B5 -> 45475
B7: =Site_Information!B7 -> 40 CFR Part 60 - Standards of Performance for Crude Oil and Natural Gas Facilities for which Construction, Modification or Reconstruction Commenced After September 18, 2015, and on or before December 6, 2022 - 60.5422a Semiannual Report
B9: An owner or operator must include the following information in the initial semiannual report in addition to the information required in §60.487a(b)(1) through (4): Number of pressure relief devices subject to the requirements of §60.5401a(b)
B10: except for those pressure relief devices designated for no detectable emissions under the provisions of §60.482-4a(a) and those pressure relief devices complying with §60.482-4a(c).
B11: Note: Site Record No. selections will appear once information entered onto the Site_Information tab.
B12: Site Record No. (Select from dropdown list) | C12: Process unit Identification (§60.487a(b)(1), §60.5422a(b)) | D12: Number of pressure relief devices subject to the requirements of §60.5401a(b) except for those designated for no detectable emissions and those complying with §60.482-4a(c) (§60.5422a(b)) | E12: Number of valves subject to the requirements of §60.482–7a, excluding those valves designated for no detectable emissions under the provisions of §60.482–7a(f) (§60.487a(b)(2), §60.5422a(b)) | F12: Number of pumps subject to the requirements of §60.482–2a, excluding those pumps designated for no detectable emissions under the provisions of §60.482–2a(e) and those pumps complying with §60.482–2a(f) (§60.487a(b)(3), §60.5422a(b)) | G12: Number of connectors subject to the requirements of §60.482–11a (§60.487a(b)(5), §60.5422a(b))
B13: RecordId | C13: ProcessUnitID | D13: InPreRelDevCt | E13: InValveCt | F13: InPumpCt | G13: InConnectorCt
B14: e.g.: 1 | C14: e.g.: HVDry-1a | D14: e.g.: 5 | E14: e.g.: 5 | F14: e.g.: 5 | G14: e.g.: 5
B15: e.g.: | C15: e.g.: | D15: e.g.: | E15: e.g.: | F15: e.g.: | G15: e.g.:
B16: e.g.: | C16: e.g.: | D16: e.g.: | E16: e.g.: | F16: e.g.: | G16: e.g.:
B17: e.g.: | C17: e.g.: | D17: e.g.: | E17: e.g.: | F17: e.g.: | G17: e.g.:
B18: e.g.: | C18: e.g.: | D18: e.g.: | E18: e.g.: | F18: e.g.: | G18: e.g.:
B19: e.g.: | C19: e.g.: | D19: e.g.: | E19: e.g.: | F19: e.g.: | G19: e.g.:
B20: e.g.: | C20: e.g.: | D20: e.g.: | E20: e.g.: | F20: e.g.: | G20: e.g.:
B21: e.g.: | C21: e.g.: | D21: e.g.: | E21: e.g.: | F21: e.g.: | G21: e.g.:
B22: e.g.: | C22: e.g.: | D22: e.g.: | E22: e.g.: | F22: e.g.: | G22: e.g.:
B23: e.g.: | C23: e.g.: | D23: e.g.: | E23: e.g.: | F23: e.g.: | G23: e.g.:
B24: DC2 | C24: DC2 | D24: 8 | E24: 1385 | F24: 2 | G24: 4569

Sheet Semiannual_Report
B1: =Welcome!A1 -> 0
B2: =Welcome!A2 -> Template Name | C2: =Welcome!B2 -> 60.5422a Semiannual Report (Spreadsheet Template)
B3: =Welcome!A3 -> CitationID | C3: =Welcome!B3 -> 60.5422a
B4: =Welcome!A4 -> Template Version | C4: =Welcome!B4 -> v2.01
B5: =Welcome!A5 -> Last Updated Date | C5: =Welcome!B5 -> 45475
B7: =Site_Information!B7 -> 40 CFR Part 60 - Standards of Performance for Crude Oil and Natural Gas Facilities for which Construction, Modification or Reconstruction Commenced After September 18, 2015, and on or before December 6, 2022 - 60.5422a Semiannual Report
B8: An owner or operator must include the information specified in paragraphs (c)(1) and (2) of this section in all semiannual reports in addition to the information required in § 60.487a(c)(2)(i) through (iv) and (vii) through (viii):
B9: (1) Number of pressure relief devices for which leaks were detected as required in § 60.5401a(b)(2); and (2) Number of pressure relief devices for which leaks were not repaired as required in § 60.5401a(b)(3).
B11: Note: Site Record No. selections will appear once information entered onto the Site_Information tab.
B12: Facility Record No. (Select from dropdown list) | C12: Month Identification (Select from dropdown list) | D12: Number of pressure relief devices for which leaks were detected (§60.5422a(c)(1)) | E12: Number of pressure relief devices for which leaks were not repaired as required in §60.5401a(b)(3) (§60.5422a(c)(2)) | F12: Number of valves for which leaks were detected (§60.487a(c)(2)(i), §60.5422a(c)) | G12: Number of valves for which leaks were not repaired as required in §60.482–7a(d)(1) (§60.487a(c)(2)(ii), §60.5422a(c)) | H12: Number of pumps for which leaks were detected (§60.487a(c)(2)(iii), §60.5422a(c)) | I12: Number of pumps for which leaks were not repaired as required in §60.482–2a(c)(1) and (d)(6) (§60.487a(c)(2)(iv), §60.5422a(c)) | J12: Number of connectors for which leaks were detected (§60.487a(c)(2)(vii), §60.5422a(c)) | K12: Number of connectors for which leaks were not repaired as required in §60.482–11a(d) (§60.487a(c)(2)(viii), §60.5422a(c))
B13: RecordId | C13: MonthID | D13: SAPreRelDevCt | E13: SAPreRelDevNRCt | F13: SAValveCt | G13: SAValveNRCt | H13: SAPumpCt | I13: SAPumpNRCt | J13: SAConnectorCt | K13: SAConnectorNRCt
B14: e.g.: 1 | C14: e.g.: March | D14: e.g.: 5 | E14: e.g.: 5 | F14: e.g.: 5 | G14: e.g.: 5 | H14: e.g.: 5 | I14: e.g.: 5 | J14: e.g.: 5 | K14: e.g.: 5
B15: e.g.: | C15: e.g.: | D15: e.g.: | E15: e.g.: | F15: e.g.: | G15: e.g.: | H15: e.g.: | I15: e.g.: | J15: e.g.: | K15: e.g.:
B16: e.g.: | C16: e.g.: | D16: e.g.: | E16: e.g.: | F16: e.g.: | G16: e.g.: | H16: e.g.: | I16: e.g.: | J16: e.g.: | K16: e.g.:
B17: e.g.: | C17: e.g.: | D17: e.g.: | E17: e.g.: | F17: e.g.: | G17: e.g.: | H17: e.g.: | I17: e.g.: | J17: e.g.: | K17: e.g.:
B18: e.g.: | C18: e.g.: | D18: e.g.: | E18: e.g.: | F18: e.g.: | G18: e.g.: | H18: e.g.: | I18: e.g.: | J18: e.g.: | K18: e.g.:
B19: e.g.: | C19: e.g.: | D19: e.g.: | E19: e.g.: | F19: e.g.: | G19: e.g.: | H19: e.g.: | I19: e.g.: | J19: e.g.: | K19: e.g.:
B20: e.g.: | C20: e.g.: | D20: e.g.: | E20: e.g.: | F20: e.g.: | G20: e.g.: | H20: e.g.: | I20: e.g.: | J20: e.g.: | K20: e.g.:
B21: e.g.: | C21: e.g.: | D21: e.g.: | E21: e.g.: | F21: e.g.: | G21: e.g.: | H21: e.g.: | I21: e.g.: | J21: e.g.: | K21: e.g.:
B22: e.g.: | C22: e.g.: | D22: e.g.: | E22: e.g.: | F22: e.g.: | G22: e.g.: | H22: e.g.: | I22: e.g.: | J22: e.g.: | K22: e.g.:
B23: e.g.: | C23: e.g.: | D23: e.g.: | E23: e.g.: | F23: e.g.: | G23: e.g.: | H23: e.g.: | I23: e.g.: | J23: e.g.: | K23: e.g.:
B24: DC2 | C24: December | D24: 0 | E24: 0 | F24: 2 | G24: 0 | H24: 0 | I24: 0 | J24: 0 | K24: 0
B25: DC2 | C25: January | D25: 0 | E25: 0 | F25: 5 | G25: 0 | H25: 0 | I25: 0 | J25: 0 | K25: 0
B26: DC2 | C26: February | D26: 0 | E26: 0 | F26: 12 | G26: 0 | H26: 0 | I26: 0 | J26: 0 | K26: 0
B27: DC2 | C27: March | D27: 0 | E27: 0 | F27: 2 | G27: 0 | H27: 0 | I27: 0 | J27: 0 | K27: 0
B28: DC2 | C28: April | D28: 0 | E28: 0 | F28: 0 | G28: 0 | H28: 0 | I28: 0 | J28: 0 | K28: 0
B29: DC2 | C29: May | D29: 0 | E29: 0 | F29: 12 | G29: 0 | H29: 0 | I29: 0 | J29: 0 | K29: 0

Sheet Lists
A1: Num | B1: Company Name | C1: CompanyList | E1: States | G1: Months
A2: =IF(B2="","",MAX(A1:A$1)+1) -> 1 | B2: {=IF(SUMPRODUCT(--(LEN(Site_Information!B24:B223)>0))>0,IF(Site_Information!B24="","",Site_Information!B24),"Add a site in the Site Information tab")} -> DC2 | C2: =+IFERROR(INDEX($B$2:$B$201,MATCH(ROW()-ROW($C$1),$A$2:$A$201,0)),"") -> DC2 | E2: AK | G2: January
A3: =IF(B3="","",MAX(A$1:A2)+1) | B3: =IF(Site_Information!B25="","",Site_Information!B25) | C3: =+IFERROR(INDEX($B$2:$B$201,MATCH(ROW()-ROW($C$1),$A$2:$A$201,0)),"") | E3: AL | G3: February
A4: =IF(B4="","",MAX(A$1:A3)+1) | B4: =IF(Site_Information!B26="","",Site_Information!B26) | C4: =+IFERROR(INDEX($B$2:$B$201,MATCH(ROW()-ROW($C$1),$A$2:$A$201,0)),"") | E4: AR | G4: March
A5: =IF(B5="","",MAX(A$1:A4)+1) | B5: =IF(Site_Information!B27="","",Site_Information!B27) | C5: =+IFERROR(INDEX($B$2:$B$201,MATCH(ROW()-ROW($C$1),$A$2:$A$201,0)),"") | E5: AS | G5: April
A6: =IF(B6="","",MAX(A$1:A5)+1) | B6: =IF(Site_Information!B28="","",Site_Information!B28) | C6: =+IFERROR(INDEX($B$2:$B$201,MATCH(ROW()-ROW($C$1),$A$2:$A$201,0)),"") | E6: AZ | G6: May
A7: =IF(B7="","",MAX(A$1:A6)+1) | B7: =IF(Site_Information!B29="","",Site_Information!B29) | C7: =+IFERROR(INDEX($B$2:$B$201,MATCH(ROW()-ROW($C$1),$A$2:$A$201,0)),"") | E7: CA | G7: June
A8: =IF(B8="","",MAX(A$1:A7)+1) | B8: =IF(Site_Information!B30="","",Site_Information!B30) | C8: =+IFERROR(INDEX($B$2:$B$201,MATCH(ROW()-ROW($C$1),$A$2:$A$201,0)),"") | E8: CO | G8: July
A9: =IF(B9="","",MAX(A$1:A8)+1) | B9: =IF(Site_Information!B31="","",Site_Information!B31) | C9: =+IFERROR(INDEX($B$2:$B$201,MATCH(ROW()-ROW($C$1),$A$2:$A$201,0)),"") | E9: CT | G9: August
A10: =IF(B10="","",MAX(A$1:A9)+1) | B10: =IF(Site_Information!B32="","",Site_Information!B32) | C10: =+IFERROR(INDEX($B$2:$B$201,MATCH(ROW()-ROW($C$1),$A$2:$A$201,0)),"") | E10: DC | G10: September
A11: =IF(B11="","",MAX(A$1:A10)+1) | B11: =IF(Site_Information!B33="","",Site_Information!B33) | C11: =+IFERROR(INDEX($B$2:$B$201,MATCH(ROW()-ROW($C$1),$A$2:$A$201,0)),"") | E11: DE | G11: October
A12: =IF(B12="","",MAX(A$1:A11)+1) | B12: =IF(Site_Information!B34="","",Site_Information!B34) | C12: =+IFERROR(INDEX($B$2:$B$201,MATCH(ROW()-ROW($C$1),$A$2:$A$201,0)),"") | E12: FL | G12: November
A13: =IF(B13="","",MAX(A$1:A12)+1) | B13: =IF(Site_Information!B35="","",Site_Information!B35) | C13: =+IFERROR(INDEX($B$2:$B$201,MATCH(ROW()-ROW($C$1),$A$2:$A$201,0)),"") | E13: GA | G13: December
A14: =IF(B14="","",MAX(A$1:A13)+1) | B14: =IF(Site_Information!B36="","",Site_Information!B36) | C14: =+IFERROR(INDEX($B$2:$B$201,MATCH(ROW()-ROW($C$1),$A$2:$A$201,0)),"") | E14: GU
A15: =IF(B15="","",MAX(A$1:A14)+1) | B15: =IF(Site_Information!B37="","",Site_Information!B37) | C15: =+IFERROR(INDEX($B$2:$B$201,MATCH(ROW()-ROW($C$1),$A$2:$A$201,0)),"") | E15: HI
A16: =IF(B16="","",MAX(A$1:A15)+1) | B16: =IF(Site_Information!B38="","",Site_Information!B38) | C16: =+IFERROR(INDEX($B$2:$B$201,MATCH(ROW()-ROW($C$1),$A$2:$A$201,0)),"") | E16: IA
A17: =IF(B17="","",MAX(A$1:A16)+1) | B17: =IF(Site_Information!B39="","",Site_Information!B39) | C17: =+IFERROR(INDEX($B$2:$B$201,MATCH(ROW()-ROW($C$1),$A$2:$A$201,0)),"") | E17: ID
A18: =IF(B18="","",MAX(A$1:A17)+1) | B18: =IF(Site_Information!B40="","",Site_Information!B40) | C18: =+IFERROR(INDEX($B$2:$B$201,MATCH(ROW()-ROW($C$1),$A$2:$A$201,0)),"") | E18: IL
A19: =IF(B19="","",MAX(A$1:A18)+1) | B19: =IF(Site_Information!B41="","",Site_Information!B41) | C19: =+IFERROR(INDEX($B$2:$B$201,MATCH(ROW()-ROW($C$1),$A$2:$A$201,0)),"") | E19: IN
A20: =IF(B20="","",MAX(A$1:A19)+1) | B20: =IF(Site_Information!B42="","",Site_Information!B42) | C20: =+IFERROR(INDEX($B$2:$B$201,MATCH(ROW()-ROW($C$1),$A$2:$A$201,0)),"") | E20: KS
A21: =IF(B21="","",MAX(A$1:A20)+1) | B21: =IF(Site_Information!B43="","",Site_Information!B43) | C21: =+IFERROR(INDEX($B$2:$B$201,MATCH(ROW()-ROW($C$1),$A$2:$A$201,0)),"") | E21: KY
A22: =IF(B22="","",MAX(A$1:A21)+1) | B22: =IF(Site_Information!B44="","",Site_Information!B44) | C22: =+IFERROR(INDEX($B$2:$B$201,MATCH(ROW()-ROW($C$1),$A$2:$A$201,0)),"") | E22: LA
A23: =IF(B23="","",MAX(A$1:A22)+1) | B23: =IF(Site_Information!B45="","",Site_Information!B45) | C23: =+IFERROR(INDEX($B$2:$B$201,MATCH(ROW()-ROW($C$1),$A$2:$A$201,0)),"") | E23: MA
A24: =IF(B24="","",MAX(A$1:A23)+1) | B24: =IF(Site_Information!B46="","",Site_Information!B46) | C24: =+IFERROR(INDEX($B$2:$B$201,MATCH(ROW()-ROW($C$1),$A$2:$A$201,0)),"") | E24: MD
A25: =IF(B25="","",MAX(A$1:A24)+1) | B25: =IF(Site_Information!B47="","",Site_Information!B47) | C25: =+IFERROR(INDEX($B$2:$B$201,MATCH(ROW()-ROW($C$1),$A$2:$A$201,0)),"") | E25: ME
... A57: =IF(B57="","",MAX(A$1:A56)+1) | B57: =IF(Site_Information!B79="","",Site_Information!B79) | C57: =+IFERROR(INDEX($B$2:$B$201,MATCH(ROW()-ROW($C$1),$A$2:$A$201,0)),"") | E57: WY
A58: =IF(B58="","",MAX(A$1:A57)+1) | B58: =IF(Site_Information!B80="","",Site_Information!B80) | C58: =+IFERROR(INDEX($B$2:$B$201,MATCH(ROW()-ROW($C$1),$A$2:$A$201,0)),"")
A59: =IF(B59="","",MAX(A$1:A58)+1) | B59: =IF(Site_Information!B81="","",Site_Information!B81) | C59: =+IFERROR(INDEX($B$2:$B$201,MATCH(ROW()-ROW($C$1),$A$2:$A$201,0)),"")
A60: =IF(B60="","",MAX(A$1:A59)+1) | B60: =IF(Site_Information!B82="","",Site_Information!B82) | C60: =+IFERROR(INDEX($B$2:$B$201,MATCH(ROW()-ROW($C$1),$A$2:$A$201,0)),"")
A61: =IF(B61="","",MAX(A$1:A60)+1) | B61: =IF(Site_Information!B83="","",Site_Information!B83) | C61: =+IFERROR(INDEX($B$2:$B$201,MATCH(ROW()-ROW($C$1),$A$2:$A$201,0)),"")
A62: =IF(B62="","",MAX(A$1:A61)+1) | B62: =IF(Site_Information!B84="","",Site_Information!B84) | C62: =+IFERROR(INDEX($B$2:$B$201,MATCH(ROW()-ROW($C$1),$A$2:$A$201,0)),"")
A63: =IF(B63="","",MAX(A$1:A62)+1) | B63: =IF(Site_Information!B85="","",Site_Information!B85) | C63: =+IFERROR(INDEX($B$2:$B$201,MATCH(ROW()-ROW($C$1),$A$2:$A$201,0)),"")
A64: =IF(B64="","",MAX(A$1:A63)+1) | B64: =IF(Site_Information!B86="","",Site_Information!B86) | C64: =+IFERROR(INDEX($B$2:$B$201,MATCH(ROW()-ROW($C$1),$A$2:$A$201,0)),"")
A65: =IF(B65="","",MAX(A$1:A64)+1) | B65: =IF(Site_Information!B87="","",Site_Information!B87) | C65: =+IFERROR(INDEX($B$2:$B$201,MATCH(ROW()-ROW($C$1),$A$2:$A$201,0)),"")
A66: =IF(B66="","",MAX(A$1:A65)+1) | B66: =IF(Site_Information!B88="","",Site_Information!B88) | C66: =+IFERROR(INDEX($B$2:$B$201,MATCH(ROW()-ROW($C$1),$A$2:$A$201,0)),"")
A67: =IF(B67="","",MAX(A$1:A66)+1) | B67: =IF(Site_Information!B89="","",Site_Information!B89) | C67: =+IFERROR(INDEX($B$2:$B$201,MATCH(ROW()-ROW($C$1),$A$2:$A$201,0)),"")
A68: =IF(B68="","",MAX(A$1:A67)+1) | B68: =IF(Site_Information!B90="","",Site_Information!B90) | C68: =+IFERROR(INDEX($B$2:$B$201,MATCH(ROW()-ROW($C$1),$A$2:$A$201,0)),"")
A69: =IF(B69="","",MAX(A$1:A68)+1) | B69: =IF(Site_Information!B91="","",Site_Information!B91) | C69: =+IFERROR(INDEX($B$2:$B$201,MATCH(ROW()-ROW($C$1),$A$2:$A$201,0)),"")
... A201: =IF(B201="","",MAX(A$1:A200)+1) | B201: =IF(Site_Information!B223="","",Site_Information!B223) | C201: =+IFERROR(INDEX($B$2:$B$201,MATCH(ROW()-ROW($C$1),$A$2:$A$201,0)),"")

Sheet Worksheet Map
A1: Worksheet Name | B1: Parent | C1: JSON Key | D1: Parent Primary Key | E1: Child Foreign Key
A2: Site_Information | C2: records
A3: Initial_Report | B3: records | C3: InitialReport | D3: RecordId | E3: RecordId
A4: Semiannual_Report | B4: records | C4: SemiannualReport | D4: RecordId | E4: RecordId

Sheet Revisions
A1: Revision Number | B1: Date | C1: Description
A2: 2 | B2: 45441
A3: 2.01 | B3: 45475 | C3: updated welcome tab
